Microsoft Windows [Version 10.0.19045.4412]
(c) Microsoft Corporation. All rights reserved.

C:\Users\LENOVO>cd Desktop

C:\Users\LENOVO\Desktop>cd Demo

C:\Users\LENOVO\Desktop\Demo>dir
 Volume in drive C has no label.
 Volume Serial Number is EC1F-E4A3

 Directory of C:\Users\LENOVO\Desktop\Demo

11/07/2024  12:17 pm    <DIR>          .
11/07/2024  12:17 pm    <DIR>          ..
11/07/2024  12:17 pm    <DIR>          myworld
               0 File(s)              0 bytes
               3 Dir(s)  66,731,487,232 bytes free

C:\Users\LENOVO\Desktop\Demo>myworld\Scripts\activate.bat

(myworld) C:\Users\LENOVO\Desktop\Demo>pip -m pip install django

Usage:
  pip <command> [options]

no such option: -m

(myworld) C:\Users\LENOVO\Desktop\Demo>django-admin --version
'django-admin' is not recognized as an internal or external command,
operable program or batch file.

(myworld) C:\Users\LENOVO\Desktop\Demo>pip --version
pip 21.2.4 from C:\Users\LENOVO\Desktop\Demo\myworld\lib\site-packages\pip (python 3.9)

(myworld) C:\Users\LENOVO\Desktop\Demo>python --version
Python 3.9.9

(myworld) C:\Users\LENOVO\Desktop\Demo>py -m pip install django
Collecting django
  Downloading Django-4.2.14-py3-none-any.whl (8.0 MB)
     |████████████████████████████████| 8.0 MB 1.6 MB/s
Collecting asgiref<4,>=3.6.0
  Using cached asgiref-3.8.1-py3-none-any.whl (23 kB)
Collecting sqlparse>=0.3.1
  Using cached sqlparse-0.5.0-py3-none-any.whl (43 kB)
Collecting tzdata
  Using cached tzdata-2024.1-py2.py3-none-any.whl (345 kB)
Collecting typing-extensions>=4
  Using cached typing_extensions-4.12.2-py3-none-any.whl (37 kB)
Installing collected packages: typing-extensions, tzdata, sqlparse, asgiref, django
Successfully installed asgiref-3.8.1 django-4.2.14 sqlparse-0.5.0 typing-extensions-4.12.2 tzdata-2024.1

(myworld) C:\Users\LENOVO\Desktop\Demo>ls -l
'ls' is not recognized as an internal or external command,
operable program or batch file.

(myworld) C:\Users\LENOVO\Desktop\Demo>dir
 Volume in drive C has no label.
 Volume Serial Number is EC1F-E4A3

 Directory of C:\Users\LENOVO\Desktop\Demo

11/07/2024  12:17 pm    <DIR>          .
11/07/2024  12:17 pm    <DIR>          ..
11/07/2024  12:17 pm    <DIR>          myworld
               0 File(s)              0 bytes
               3 Dir(s)  66,678,104,064 bytes free

(myworld) C:\Users\LENOVO\Desktop\Demo>django-admin --version
4.2.14

(myworld) C:\Users\LENOVO\Desktop\Demo>cd myworld

(myworld) C:\Users\LENOVO\Desktop\Demo\myworld>django-admin --version
4.2.14

(myworld) C:\Users\LENOVO\Desktop\Demo\myworld>django-admin startproject my-tennis_club
CommandError: 'my-tennis_club' is not a valid project name. Please make sure the name is a valid identifier.

(myworld) C:\Users\LENOVO\Desktop\Demo\myworld>django-admin startproject my_tennis_club

(myworld) C:\Users\LENOVO\Desktop\Demo\myworld>dir
 Volume in drive C has no label.
 Volume Serial Number is EC1F-E4A3

 Directory of C:\Users\LENOVO\Desktop\Demo\myworld

11/07/2024  12:36 pm    <DIR>          .
11/07/2024  12:36 pm    <DIR>          ..
11/07/2024  12:17 pm    <DIR>          Include
11/07/2024  12:17 pm    <DIR>          Lib
11/07/2024  12:36 pm    <DIR>          my_tennis_club
11/07/2024  12:17 pm               118 pyvenv.cfg
11/07/2024  12:34 pm    <DIR>          Scripts
               1 File(s)            118 bytes
               6 Dir(s)  66,680,254,464 bytes free

(myworld) C:\Users\LENOVO\Desktop\Demo\myworld>cd ..

(myworld) C:\Users\LENOVO\Desktop\Demo>code .

(myworld) C:\Users\LENOVO\Desktop\Demo>dir
 Volume in drive C has no label.
 Volume Serial Number is EC1F-E4A3

 Directory of C:\Users\LENOVO\Desktop\Demo

11/07/2024  12:17 pm    <DIR>          .
11/07/2024  12:17 pm    <DIR>          ..
11/07/2024  12:36 pm    <DIR>          myworld
               0 File(s)              0 bytes
               3 Dir(s)  66,625,540,096 bytes free

(myworld) C:\Users\LENOVO\Desktop\Demo>cd myworld

(myworld) C:\Users\LENOVO\Desktop\Demo\myworld>dir
 Volume in drive C has no label.
 Volume Serial Number is EC1F-E4A3

 Directory of C:\Users\LENOVO\Desktop\Demo\myworld

11/07/2024  12:36 pm    <DIR>          .
11/07/2024  12:36 pm    <DIR>          ..
11/07/2024  12:17 pm    <DIR>          Include
11/07/2024  12:17 pm    <DIR>          Lib
11/07/2024  12:36 pm    <DIR>          my_tennis_club
11/07/2024  12:17 pm               118 pyvenv.cfg
11/07/2024  12:34 pm    <DIR>          Scripts
               1 File(s)            118 bytes
               6 Dir(s)  66,625,540,096 bytes free

(myworld) C:\Users\LENOVO\Desktop\Demo\myworld>cd my_tennis_club

(myworld) C:\Users\LENOVO\Desktop\Demo\myworld\my_tennis_club>py manage.py runserver
Watching for file changes with StatReloader
Performing system checks...

System check identified no issues (0 silenced).

You have 18 unapplied migration(s). Your project may not work properly until you apply the migrations for app(s): admin, auth, contenttypes, sessions.
Run 'python manage.py migrate' to apply them.
July 11, 2024 - 12:40:08
Django version 4.2.14, using settings 'my_tennis_club.settings'
Starting development server at http://127.0.0.1:8000/
Quit the server with CTRL-BREAK.

[11/Jul/2024 12:41:48] "GET / HTTP/1.1" 200 10664
Not Found: /favicon.ico
[11/Jul/2024 12:41:50] "GET /favicon.ico HTTP/1.1" 404 2118

(myworld) C:\Users\LENOVO\Desktop\Demo\myworld\my_tennis_club>py manage.py startapp members

(myworld) C:\Users\LENOVO\Desktop\Demo\myworld\my_tennis_club>py manage.py runserver
Watching for file changes with StatReloader
Performing system checks...

System check identified no issues (0 silenced).

You have 18 unapplied migration(s). Your project may not work properly until you apply the migrations for app(s): admin, auth, contenttypes, sessions.
Run 'python manage.py migrate' to apply them.
July 11, 2024 - 12:59:51
Django version 4.2.14, using settings 'my_tennis_club.settings'
Starting development server at http://127.0.0.1:8000/
Quit the server with CTRL-BREAK.

[11/Jul/2024 13:00:27] "GET /members/ HTTP/1.1" 200 12
C:\Users\LENOVO\Desktop\Demo\myworld\my_tennis_club\my_tennis_club\urls.py changed, reloading.
Watching for file changes with StatReloader
Performing system checks...

System check identified no issues (0 silenced).

You have 18 unapplied migration(s). Your project may not work properly until you apply the migrations for app(s): admin, auth, contenttypes, sessions.
Run 'python manage.py migrate' to apply them.
July 11, 2024 - 13:00:48
Django version 4.2.14, using settings 'my_tennis_club.settings'
Starting development server at http://127.0.0.1:8000/
Quit the server with CTRL-BREAK.

[11/Jul/2024 13:00:57] "GET /members/ HTTP/1.1" 200 12
[11/Jul/2024 13:00:59] "GET /members/ HTTP/1.1" 200 12
[11/Jul/2024 13:01:04] "GET /members/ HTTP/1.1" 200 12
C:\Users\LENOVO\Desktop\Demo\myworld\my_tennis_club\my_tennis_club\urls.py changed, reloading.
Watching for file changes with StatReloader
Performing system checks...

System check identified no issues (0 silenced).

You have 18 unapplied migration(s). Your project may not work properly until you apply the migrations for app(s): admin, auth, contenttypes, sessions.
Run 'python manage.py migrate' to apply them.
July 11, 2024 - 13:01:27
Django version 4.2.14, using settings 'my_tennis_club.settings'
Starting development server at http://127.0.0.1:8000/
Quit the server with CTRL-BREAK.

C:\Users\LENOVO\Desktop\Demo\myworld\my_tennis_club\members\views.py changed, reloading.
Watching for file changes with StatReloader
Performing system checks...

Exception in thread django-main-thread:
Traceback (most recent call last):
  File "C:\Users\LENOVO\AppData\Local\Programs\Python\Python39\lib\threading.py", line 973, in _bootstrap_inner
    self.run()
  File "C:\Users\LENOVO\AppData\Local\Programs\Python\Python39\lib\threading.py", line 910, in run
    self._target(*self._args, **self._kwargs)
  File "C:\Users\LENOVO\Desktop\Demo\myworld\lib\site-packages\django\utils\autoreload.py", line 64, in wrapper
    fn(*args, **kwargs)
  File "C:\Users\LENOVO\Desktop\Demo\myworld\lib\site-packages\django\core\management\commands\runserver.py", line 133, in inner_run
    self.check(display_num_errors=True)
  File "C:\Users\LENOVO\Desktop\Demo\myworld\lib\site-packages\django\core\management\base.py", line 485, in check
    all_issues = checks.run_checks(
  File "C:\Users\LENOVO\Desktop\Demo\myworld\lib\site-packages\django\core\checks\registry.py", line 88, in run_checks
    new_errors = check(app_configs=app_configs, databases=databases)
  File "C:\Users\LENOVO\Desktop\Demo\myworld\lib\site-packages\django\core\checks\urls.py", line 14, in check_url_config
    return check_resolver(resolver)
  File "C:\Users\LENOVO\Desktop\Demo\myworld\lib\site-packages\django\core\checks\urls.py", line 24, in check_resolver
    return check_method()
  File "C:\Users\LENOVO\Desktop\Demo\myworld\lib\site-packages\django\urls\resolvers.py", line 494, in check
    for pattern in self.url_patterns:
  File "C:\Users\LENOVO\Desktop\Demo\myworld\lib\site-packages\django\utils\functional.py", line 57, in __get__
    res = instance.__dict__[self.name] = self.func(instance)
  File "C:\Users\LENOVO\Desktop\Demo\myworld\lib\site-packages\django\urls\resolvers.py", line 715, in url_patterns
    patterns = getattr(self.urlconf_module, "urlpatterns", self.urlconf_module)
  File "C:\Users\LENOVO\Desktop\Demo\myworld\lib\site-packages\django\utils\functional.py", line 57, in __get__
    res = instance.__dict__[self.name] = self.func(instance)
  File "C:\Users\LENOVO\Desktop\Demo\myworld\lib\site-packages\django\urls\resolvers.py", line 708, in urlconf_module
    return import_module(self.urlconf_name)
  File "C:\Users\LENOVO\AppData\Local\Programs\Python\Python39\lib\importlib\__init__.py", line 127, in import_module
    return _bootstrap._gcd_import(name[level:], package, level)
  File "<frozen importlib._bootstrap>", line 1030, in _gcd_import
  File "<frozen importlib._bootstrap>", line 1007, in _find_and_load
  File "<frozen importlib._bootstrap>", line 986, in _find_and_load_unlocked
  File "<frozen importlib._bootstrap>", line 680, in _load_unlocked
  File "<frozen importlib._bootstrap_external>", line 850, in exec_module
  File "<frozen importlib._bootstrap>", line 228, in _call_with_frames_removed
  File "C:\Users\LENOVO\Desktop\Demo\myworld\my_tennis_club\my_tennis_club\urls.py", line 21, in <module>
    path('',include('members.urls')),
  File "C:\Users\LENOVO\Desktop\Demo\myworld\lib\site-packages\django\urls\conf.py", line 38, in include
    urlconf_module = import_module(urlconf_module)
  File "C:\Users\LENOVO\AppData\Local\Programs\Python\Python39\lib\importlib\__init__.py", line 127, in import_module
    return _bootstrap._gcd_import(name[level:], package, level)
  File "<frozen importlib._bootstrap>", line 1030, in _gcd_import
  File "<frozen importlib._bootstrap>", line 1007, in _find_and_load
  File "<frozen importlib._bootstrap>", line 986, in _find_and_load_unlocked
  File "<frozen importlib._bootstrap>", line 680, in _load_unlocked
  File "<frozen importlib._bootstrap_external>", line 850, in exec_module
  File "<frozen importlib._bootstrap>", line 228, in _call_with_frames_removed
  File "C:\Users\LENOVO\Desktop\Demo\myworld\my_tennis_club\members\urls.py", line 2, in <module>
    from . import views
  File "C:\Users\LENOVO\Desktop\Demo\myworld\my_tennis_club\members\views.py", line 3
    from django.temaplate import
                                 ^
SyntaxError: invalid syntax
C:\Users\LENOVO\Desktop\Demo\myworld\my_tennis_club\members\views.py changed, reloading.
Watching for file changes with StatReloader
Performing system checks...

Exception in thread django-main-thread:
Traceback (most recent call last):
  File "C:\Users\LENOVO\AppData\Local\Programs\Python\Python39\lib\threading.py", line 973, in _bootstrap_inner
    self.run()
  File "C:\Users\LENOVO\AppData\Local\Programs\Python\Python39\lib\threading.py", line 910, in run
    self._target(*self._args, **self._kwargs)
  File "C:\Users\LENOVO\Desktop\Demo\myworld\lib\site-packages\django\utils\autoreload.py", line 64, in wrapper
    fn(*args, **kwargs)
  File "C:\Users\LENOVO\Desktop\Demo\myworld\lib\site-packages\django\core\management\commands\runserver.py", line 133, in inner_run
    self.check(display_num_errors=True)
  File "C:\Users\LENOVO\Desktop\Demo\myworld\lib\site-packages\django\core\management\base.py", line 485, in check
    all_issues = checks.run_checks(
  File "C:\Users\LENOVO\Desktop\Demo\myworld\lib\site-packages\django\core\checks\registry.py", line 88, in run_checks
    new_errors = check(app_configs=app_configs, databases=databases)
  File "C:\Users\LENOVO\Desktop\Demo\myworld\lib\site-packages\django\core\checks\urls.py", line 14, in check_url_config
    return check_resolver(resolver)
  File "C:\Users\LENOVO\Desktop\Demo\myworld\lib\site-packages\django\core\checks\urls.py", line 24, in check_resolver
    return check_method()
  File "C:\Users\LENOVO\Desktop\Demo\myworld\lib\site-packages\django\urls\resolvers.py", line 494, in check
    for pattern in self.url_patterns:
  File "C:\Users\LENOVO\Desktop\Demo\myworld\lib\site-packages\django\utils\functional.py", line 57, in __get__
    res = instance.__dict__[self.name] = self.func(instance)
  File "C:\Users\LENOVO\Desktop\Demo\myworld\lib\site-packages\django\urls\resolvers.py", line 715, in url_patterns
    patterns = getattr(self.urlconf_module, "urlpatterns", self.urlconf_module)
  File "C:\Users\LENOVO\Desktop\Demo\myworld\lib\site-packages\django\utils\functional.py", line 57, in __get__
    res = instance.__dict__[self.name] = self.func(instance)
  File "C:\Users\LENOVO\Desktop\Demo\myworld\lib\site-packages\django\urls\resolvers.py", line 708, in urlconf_module
    return import_module(self.urlconf_name)
  File "C:\Users\LENOVO\AppData\Local\Programs\Python\Python39\lib\importlib\__init__.py", line 127, in import_module
    return _bootstrap._gcd_import(name[level:], package, level)
  File "<frozen importlib._bootstrap>", line 1030, in _gcd_import
  File "<frozen importlib._bootstrap>", line 1007, in _find_and_load
  File "<frozen importlib._bootstrap>", line 986, in _find_and_load_unlocked
  File "<frozen importlib._bootstrap>", line 680, in _load_unlocked
  File "<frozen importlib._bootstrap_external>", line 850, in exec_module
  File "<frozen importlib._bootstrap>", line 228, in _call_with_frames_removed
  File "C:\Users\LENOVO\Desktop\Demo\myworld\my_tennis_club\my_tennis_club\urls.py", line 21, in <module>
    path('',include('members.urls')),
  File "C:\Users\LENOVO\Desktop\Demo\myworld\lib\site-packages\django\urls\conf.py", line 38, in include
    urlconf_module = import_module(urlconf_module)
  File "C:\Users\LENOVO\AppData\Local\Programs\Python\Python39\lib\importlib\__init__.py", line 127, in import_module
    return _bootstrap._gcd_import(name[level:], package, level)
  File "<frozen importlib._bootstrap>", line 1030, in _gcd_import
  File "<frozen importlib._bootstrap>", line 1007, in _find_and_load
  File "<frozen importlib._bootstrap>", line 986, in _find_and_load_unlocked
  File "<frozen importlib._bootstrap>", line 680, in _load_unlocked
  File "<frozen importlib._bootstrap_external>", line 850, in exec_module
  File "<frozen importlib._bootstrap>", line 228, in _call_with_frames_removed
  File "C:\Users\LENOVO\Desktop\Demo\myworld\my_tennis_club\members\urls.py", line 2, in <module>
    from . import views
  File "C:\Users\LENOVO\Desktop\Demo\myworld\my_tennis_club\members\views.py", line 7
    template =
               ^
SyntaxError: invalid syntax
C:\Users\LENOVO\Desktop\Demo\myworld\my_tennis_club\members\views.py changed, reloading.
Watching for file changes with StatReloader
Performing system checks...

Exception in thread django-main-thread:
Traceback (most recent call last):
  File "C:\Users\LENOVO\AppData\Local\Programs\Python\Python39\lib\threading.py", line 973, in _bootstrap_inner
    self.run()
  File "C:\Users\LENOVO\AppData\Local\Programs\Python\Python39\lib\threading.py", line 910, in run
    self._target(*self._args, **self._kwargs)
  File "C:\Users\LENOVO\Desktop\Demo\myworld\lib\site-packages\django\utils\autoreload.py", line 64, in wrapper
    fn(*args, **kwargs)
  File "C:\Users\LENOVO\Desktop\Demo\myworld\lib\site-packages\django\core\management\commands\runserver.py", line 133, in inner_run
    self.check(display_num_errors=True)
  File "C:\Users\LENOVO\Desktop\Demo\myworld\lib\site-packages\django\core\management\base.py", line 485, in check
    all_issues = checks.run_checks(
  File "C:\Users\LENOVO\Desktop\Demo\myworld\lib\site-packages\django\core\checks\registry.py", line 88, in run_checks
    new_errors = check(app_configs=app_configs, databases=databases)
  File "C:\Users\LENOVO\Desktop\Demo\myworld\lib\site-packages\django\core\checks\urls.py", line 14, in check_url_config
    return check_resolver(resolver)
  File "C:\Users\LENOVO\Desktop\Demo\myworld\lib\site-packages\django\core\checks\urls.py", line 24, in check_resolver
    return check_method()
  File "C:\Users\LENOVO\Desktop\Demo\myworld\lib\site-packages\django\urls\resolvers.py", line 494, in check
    for pattern in self.url_patterns:
  File "C:\Users\LENOVO\Desktop\Demo\myworld\lib\site-packages\django\utils\functional.py", line 57, in __get__
    res = instance.__dict__[self.name] = self.func(instance)
  File "C:\Users\LENOVO\Desktop\Demo\myworld\lib\site-packages\django\urls\resolvers.py", line 715, in url_patterns
    patterns = getattr(self.urlconf_module, "urlpatterns", self.urlconf_module)
  File "C:\Users\LENOVO\Desktop\Demo\myworld\lib\site-packages\django\utils\functional.py", line 57, in __get__
    res = instance.__dict__[self.name] = self.func(instance)
  File "C:\Users\LENOVO\Desktop\Demo\myworld\lib\site-packages\django\urls\resolvers.py", line 708, in urlconf_module
    return import_module(self.urlconf_name)
  File "C:\Users\LENOVO\AppData\Local\Programs\Python\Python39\lib\importlib\__init__.py", line 127, in import_module
    return _bootstrap._gcd_import(name[level:], package, level)
  File "<frozen importlib._bootstrap>", line 1030, in _gcd_import
  File "<frozen importlib._bootstrap>", line 1007, in _find_and_load
  File "<frozen importlib._bootstrap>", line 986, in _find_and_load_unlocked
  File "<frozen importlib._bootstrap>", line 680, in _load_unlocked
  File "<frozen importlib._bootstrap_external>", line 850, in exec_module
  File "<frozen importlib._bootstrap>", line 228, in _call_with_frames_removed
  File "C:\Users\LENOVO\Desktop\Demo\myworld\my_tennis_club\my_tennis_club\urls.py", line 21, in <module>
    path('',include('members.urls')),
  File "C:\Users\LENOVO\Desktop\Demo\myworld\lib\site-packages\django\urls\conf.py", line 38, in include
    urlconf_module = import_module(urlconf_module)
  File "C:\Users\LENOVO\AppData\Local\Programs\Python\Python39\lib\importlib\__init__.py", line 127, in import_module
    return _bootstrap._gcd_import(name[level:], package, level)
  File "<frozen importlib._bootstrap>", line 1030, in _gcd_import
  File "<frozen importlib._bootstrap>", line 1007, in _find_and_load
  File "<frozen importlib._bootstrap>", line 986, in _find_and_load_unlocked
  File "<frozen importlib._bootstrap>", line 680, in _load_unlocked
  File "<frozen importlib._bootstrap_external>", line 850, in exec_module
  File "<frozen importlib._bootstrap>", line 228, in _call_with_frames_removed
  File "C:\Users\LENOVO\Desktop\Demo\myworld\my_tennis_club\members\urls.py", line 2, in <module>
    from . import views
  File "C:\Users\LENOVO\Desktop\Demo\myworld\my_tennis_club\members\views.py", line 3, in <module>
    from django.temaplate import loader
ModuleNotFoundError: No module named 'django.temaplate'
C:\Users\LENOVO\Desktop\Demo\myworld\my_tennis_club\members\views.py changed, reloading.
Watching for file changes with StatReloader
Performing system checks...

Exception in thread django-main-thread:
Traceback (most recent call last):
  File "C:\Users\LENOVO\AppData\Local\Programs\Python\Python39\lib\threading.py", line 973, in _bootstrap_inner
    self.run()
  File "C:\Users\LENOVO\AppData\Local\Programs\Python\Python39\lib\threading.py", line 910, in run
    self._target(*self._args, **self._kwargs)
  File "C:\Users\LENOVO\Desktop\Demo\myworld\lib\site-packages\django\utils\autoreload.py", line 64, in wrapper
    fn(*args, **kwargs)
  File "C:\Users\LENOVO\Desktop\Demo\myworld\lib\site-packages\django\core\management\commands\runserver.py", line 133, in inner_run
    self.check(display_num_errors=True)
  File "C:\Users\LENOVO\Desktop\Demo\myworld\lib\site-packages\django\core\management\base.py", line 485, in check
    all_issues = checks.run_checks(
  File "C:\Users\LENOVO\Desktop\Demo\myworld\lib\site-packages\django\core\checks\registry.py", line 88, in run_checks
    new_errors = check(app_configs=app_configs, databases=databases)
  File "C:\Users\LENOVO\Desktop\Demo\myworld\lib\site-packages\django\core\checks\urls.py", line 14, in check_url_config
    return check_resolver(resolver)
  File "C:\Users\LENOVO\Desktop\Demo\myworld\lib\site-packages\django\core\checks\urls.py", line 24, in check_resolver
    return check_method()
  File "C:\Users\LENOVO\Desktop\Demo\myworld\lib\site-packages\django\urls\resolvers.py", line 494, in check
    for pattern in self.url_patterns:
  File "C:\Users\LENOVO\Desktop\Demo\myworld\lib\site-packages\django\utils\functional.py", line 57, in __get__
    res = instance.__dict__[self.name] = self.func(instance)
  File "C:\Users\LENOVO\Desktop\Demo\myworld\lib\site-packages\django\urls\resolvers.py", line 715, in url_patterns
    patterns = getattr(self.urlconf_module, "urlpatterns", self.urlconf_module)
  File "C:\Users\LENOVO\Desktop\Demo\myworld\lib\site-packages\django\utils\functional.py", line 57, in __get__
    res = instance.__dict__[self.name] = self.func(instance)
  File "C:\Users\LENOVO\Desktop\Demo\myworld\lib\site-packages\django\urls\resolvers.py", line 708, in urlconf_module
    return import_module(self.urlconf_name)
  File "C:\Users\LENOVO\AppData\Local\Programs\Python\Python39\lib\importlib\__init__.py", line 127, in import_module
    return _bootstrap._gcd_import(name[level:], package, level)
  File "<frozen importlib._bootstrap>", line 1030, in _gcd_import
  File "<frozen importlib._bootstrap>", line 1007, in _find_and_load
  File "<frozen importlib._bootstrap>", line 986, in _find_and_load_unlocked
  File "<frozen importlib._bootstrap>", line 680, in _load_unlocked
  File "<frozen importlib._bootstrap_external>", line 850, in exec_module
  File "<frozen importlib._bootstrap>", line 228, in _call_with_frames_removed
  File "C:\Users\LENOVO\Desktop\Demo\myworld\my_tennis_club\my_tennis_club\urls.py", line 21, in <module>
    path('',include('members.urls')),
  File "C:\Users\LENOVO\Desktop\Demo\myworld\lib\site-packages\django\urls\conf.py", line 38, in include
    urlconf_module = import_module(urlconf_module)
  File "C:\Users\LENOVO\AppData\Local\Programs\Python\Python39\lib\importlib\__init__.py", line 127, in import_module
    return _bootstrap._gcd_import(name[level:], package, level)
  File "<frozen importlib._bootstrap>", line 1030, in _gcd_import
  File "<frozen importlib._bootstrap>", line 1007, in _find_and_load
  File "<frozen importlib._bootstrap>", line 986, in _find_and_load_unlocked
  File "<frozen importlib._bootstrap>", line 680, in _load_unlocked
  File "<frozen importlib._bootstrap_external>", line 850, in exec_module
  File "<frozen importlib._bootstrap>", line 228, in _call_with_frames_removed
  File "C:\Users\LENOVO\Desktop\Demo\myworld\my_tennis_club\members\urls.py", line 2, in <module>
    from . import views
  File "C:\Users\LENOVO\Desktop\Demo\myworld\my_tennis_club\members\views.py", line 3, in <module>
    from django.temaplate import loader
ModuleNotFoundError: No module named 'django.temaplate'
C:\Users\LENOVO\Desktop\Demo\myworld\my_tennis_club\members\views.py changed, reloading.
Watching for file changes with StatReloader
Performing system checks...

Exception in thread django-main-thread:
Traceback (most recent call last):
  File "C:\Users\LENOVO\AppData\Local\Programs\Python\Python39\lib\threading.py", line 973, in _bootstrap_inner
    self.run()
  File "C:\Users\LENOVO\AppData\Local\Programs\Python\Python39\lib\threading.py", line 910, in run
    self._target(*self._args, **self._kwargs)
  File "C:\Users\LENOVO\Desktop\Demo\myworld\lib\site-packages\django\utils\autoreload.py", line 64, in wrapper
    fn(*args, **kwargs)
  File "C:\Users\LENOVO\Desktop\Demo\myworld\lib\site-packages\django\core\management\commands\runserver.py", line 133, in inner_run
    self.check(display_num_errors=True)
  File "C:\Users\LENOVO\Desktop\Demo\myworld\lib\site-packages\django\core\management\base.py", line 485, in check
    all_issues = checks.run_checks(
  File "C:\Users\LENOVO\Desktop\Demo\myworld\lib\site-packages\django\core\checks\registry.py", line 88, in run_checks
    new_errors = check(app_configs=app_configs, databases=databases)
  File "C:\Users\LENOVO\Desktop\Demo\myworld\lib\site-packages\django\core\checks\urls.py", line 14, in check_url_config
    return check_resolver(resolver)
  File "C:\Users\LENOVO\Desktop\Demo\myworld\lib\site-packages\django\core\checks\urls.py", line 24, in check_resolver
    return check_method()
  File "C:\Users\LENOVO\Desktop\Demo\myworld\lib\site-packages\django\urls\resolvers.py", line 494, in check
    for pattern in self.url_patterns:
  File "C:\Users\LENOVO\Desktop\Demo\myworld\lib\site-packages\django\utils\functional.py", line 57, in __get__
    res = instance.__dict__[self.name] = self.func(instance)
  File "C:\Users\LENOVO\Desktop\Demo\myworld\lib\site-packages\django\urls\resolvers.py", line 715, in url_patterns
    patterns = getattr(self.urlconf_module, "urlpatterns", self.urlconf_module)
  File "C:\Users\LENOVO\Desktop\Demo\myworld\lib\site-packages\django\utils\functional.py", line 57, in __get__
    res = instance.__dict__[self.name] = self.func(instance)
  File "C:\Users\LENOVO\Desktop\Demo\myworld\lib\site-packages\django\urls\resolvers.py", line 708, in urlconf_module
    return import_module(self.urlconf_name)
  File "C:\Users\LENOVO\AppData\Local\Programs\Python\Python39\lib\importlib\__init__.py", line 127, in import_module
    return _bootstrap._gcd_import(name[level:], package, level)
  File "<frozen importlib._bootstrap>", line 1030, in _gcd_import
  File "<frozen importlib._bootstrap>", line 1007, in _find_and_load
  File "<frozen importlib._bootstrap>", line 986, in _find_and_load_unlocked
  File "<frozen importlib._bootstrap>", line 680, in _load_unlocked
  File "<frozen importlib._bootstrap_external>", line 850, in exec_module
  File "<frozen importlib._bootstrap>", line 228, in _call_with_frames_removed
  File "C:\Users\LENOVO\Desktop\Demo\myworld\my_tennis_club\my_tennis_club\urls.py", line 21, in <module>
    path('',include('members.urls')),
  File "C:\Users\LENOVO\Desktop\Demo\myworld\lib\site-packages\django\urls\conf.py", line 38, in include
    urlconf_module = import_module(urlconf_module)
  File "C:\Users\LENOVO\AppData\Local\Programs\Python\Python39\lib\importlib\__init__.py", line 127, in import_module
    return _bootstrap._gcd_import(name[level:], package, level)
  File "<frozen importlib._bootstrap>", line 1030, in _gcd_import
  File "<frozen importlib._bootstrap>", line 1007, in _find_and_load
  File "<frozen importlib._bootstrap>", line 986, in _find_and_load_unlocked
  File "<frozen importlib._bootstrap>", line 680, in _load_unlocked
  File "<frozen importlib._bootstrap_external>", line 850, in exec_module
  File "<frozen importlib._bootstrap>", line 228, in _call_with_frames_removed
  File "C:\Users\LENOVO\Desktop\Demo\myworld\my_tennis_club\members\urls.py", line 2, in <module>
    from . import views
  File "C:\Users\LENOVO\Desktop\Demo\myworld\my_tennis_club\members\views.py", line 3, in <module>
    from django.temaplate import loader
ModuleNotFoundError: No module named 'django.temaplate'
C:\Users\LENOVO\Desktop\Demo\myworld\my_tennis_club\members\views.py changed, reloading.
Watching for file changes with StatReloader
Performing system checks...

Exception in thread django-main-thread:
Traceback (most recent call last):
  File "C:\Users\LENOVO\AppData\Local\Programs\Python\Python39\lib\threading.py", line 973, in _bootstrap_inner
    self.run()
  File "C:\Users\LENOVO\AppData\Local\Programs\Python\Python39\lib\threading.py", line 910, in run
    self._target(*self._args, **self._kwargs)
  File "C:\Users\LENOVO\Desktop\Demo\myworld\lib\site-packages\django\utils\autoreload.py", line 64, in wrapper
    fn(*args, **kwargs)
  File "C:\Users\LENOVO\Desktop\Demo\myworld\lib\site-packages\django\core\management\commands\runserver.py", line 133, in inner_run
    self.check(display_num_errors=True)
  File "C:\Users\LENOVO\Desktop\Demo\myworld\lib\site-packages\django\core\management\base.py", line 485, in check
    all_issues = checks.run_checks(
  File "C:\Users\LENOVO\Desktop\Demo\myworld\lib\site-packages\django\core\checks\registry.py", line 88, in run_checks
    new_errors = check(app_configs=app_configs, databases=databases)
  File "C:\Users\LENOVO\Desktop\Demo\myworld\lib\site-packages\django\core\checks\urls.py", line 14, in check_url_config
    return check_resolver(resolver)
  File "C:\Users\LENOVO\Desktop\Demo\myworld\lib\site-packages\django\core\checks\urls.py", line 24, in check_resolver
    return check_method()
  File "C:\Users\LENOVO\Desktop\Demo\myworld\lib\site-packages\django\urls\resolvers.py", line 494, in check
    for pattern in self.url_patterns:
  File "C:\Users\LENOVO\Desktop\Demo\myworld\lib\site-packages\django\utils\functional.py", line 57, in __get__
    res = instance.__dict__[self.name] = self.func(instance)
  File "C:\Users\LENOVO\Desktop\Demo\myworld\lib\site-packages\django\urls\resolvers.py", line 715, in url_patterns
    patterns = getattr(self.urlconf_module, "urlpatterns", self.urlconf_module)
  File "C:\Users\LENOVO\Desktop\Demo\myworld\lib\site-packages\django\utils\functional.py", line 57, in __get__
    res = instance.__dict__[self.name] = self.func(instance)
  File "C:\Users\LENOVO\Desktop\Demo\myworld\lib\site-packages\django\urls\resolvers.py", line 708, in urlconf_module
    return import_module(self.urlconf_name)
  File "C:\Users\LENOVO\AppData\Local\Programs\Python\Python39\lib\importlib\__init__.py", line 127, in import_module
    return _bootstrap._gcd_import(name[level:], package, level)
  File "<frozen importlib._bootstrap>", line 1030, in _gcd_import
  File "<frozen importlib._bootstrap>", line 1007, in _find_and_load
  File "<frozen importlib._bootstrap>", line 986, in _find_and_load_unlocked
  File "<frozen importlib._bootstrap>", line 680, in _load_unlocked
  File "<frozen importlib._bootstrap_external>", line 850, in exec_module
  File "<frozen importlib._bootstrap>", line 228, in _call_with_frames_removed
  File "C:\Users\LENOVO\Desktop\Demo\myworld\my_tennis_club\my_tennis_club\urls.py", line 21, in <module>
    path('',include('members.urls')),
  File "C:\Users\LENOVO\Desktop\Demo\myworld\lib\site-packages\django\urls\conf.py", line 38, in include
    urlconf_module = import_module(urlconf_module)
  File "C:\Users\LENOVO\AppData\Local\Programs\Python\Python39\lib\importlib\__init__.py", line 127, in import_module
    return _bootstrap._gcd_import(name[level:], package, level)
  File "<frozen importlib._bootstrap>", line 1030, in _gcd_import
  File "<frozen importlib._bootstrap>", line 1007, in _find_and_load
  File "<frozen importlib._bootstrap>", line 986, in _find_and_load_unlocked
  File "<frozen importlib._bootstrap>", line 680, in _load_unlocked
  File "<frozen importlib._bootstrap_external>", line 850, in exec_module
  File "<frozen importlib._bootstrap>", line 228, in _call_with_frames_removed
  File "C:\Users\LENOVO\Desktop\Demo\myworld\my_tennis_club\members\urls.py", line 2, in <module>
    from . import views
  File "C:\Users\LENOVO\Desktop\Demo\myworld\my_tennis_club\members\views.py", line 3, in <module>
    from django.temaplate import loader
ModuleNotFoundError: No module named 'django.temaplate'
C:\Users\LENOVO\Desktop\Demo\myworld\my_tennis_club\members\views.py changed, reloading.
Watching for file changes with StatReloader
Performing system checks...

Exception in thread django-main-thread:
Traceback (most recent call last):
  File "C:\Users\LENOVO\AppData\Local\Programs\Python\Python39\lib\threading.py", line 973, in _bootstrap_inner
    self.run()
  File "C:\Users\LENOVO\AppData\Local\Programs\Python\Python39\lib\threading.py", line 910, in run
    self._target(*self._args, **self._kwargs)
  File "C:\Users\LENOVO\Desktop\Demo\myworld\lib\site-packages\django\utils\autoreload.py", line 64, in wrapper
    fn(*args, **kwargs)
  File "C:\Users\LENOVO\Desktop\Demo\myworld\lib\site-packages\django\core\management\commands\runserver.py", line 133, in inner_run
    self.check(display_num_errors=True)
  File "C:\Users\LENOVO\Desktop\Demo\myworld\lib\site-packages\django\core\management\base.py", line 485, in check
    all_issues = checks.run_checks(
  File "C:\Users\LENOVO\Desktop\Demo\myworld\lib\site-packages\django\core\checks\registry.py", line 88, in run_checks
    new_errors = check(app_configs=app_configs, databases=databases)
  File "C:\Users\LENOVO\Desktop\Demo\myworld\lib\site-packages\django\core\checks\urls.py", line 14, in check_url_config
    return check_resolver(resolver)
  File "C:\Users\LENOVO\Desktop\Demo\myworld\lib\site-packages\django\core\checks\urls.py", line 24, in check_resolver
    return check_method()
  File "C:\Users\LENOVO\Desktop\Demo\myworld\lib\site-packages\django\urls\resolvers.py", line 494, in check
    for pattern in self.url_patterns:
  File "C:\Users\LENOVO\Desktop\Demo\myworld\lib\site-packages\django\utils\functional.py", line 57, in __get__
    res = instance.__dict__[self.name] = self.func(instance)
  File "C:\Users\LENOVO\Desktop\Demo\myworld\lib\site-packages\django\urls\resolvers.py", line 715, in url_patterns
    patterns = getattr(self.urlconf_module, "urlpatterns", self.urlconf_module)
  File "C:\Users\LENOVO\Desktop\Demo\myworld\lib\site-packages\django\utils\functional.py", line 57, in __get__
    res = instance.__dict__[self.name] = self.func(instance)
  File "C:\Users\LENOVO\Desktop\Demo\myworld\lib\site-packages\django\urls\resolvers.py", line 708, in urlconf_module
    return import_module(self.urlconf_name)
  File "C:\Users\LENOVO\AppData\Local\Programs\Python\Python39\lib\importlib\__init__.py", line 127, in import_module
    return _bootstrap._gcd_import(name[level:], package, level)
  File "<frozen importlib._bootstrap>", line 1030, in _gcd_import
  File "<frozen importlib._bootstrap>", line 1007, in _find_and_load
  File "<frozen importlib._bootstrap>", line 986, in _find_and_load_unlocked
  File "<frozen importlib._bootstrap>", line 680, in _load_unlocked
  File "<frozen importlib._bootstrap_external>", line 850, in exec_module
  File "<frozen importlib._bootstrap>", line 228, in _call_with_frames_removed
  File "C:\Users\LENOVO\Desktop\Demo\myworld\my_tennis_club\my_tennis_club\urls.py", line 21, in <module>
    path('',include('members.urls')),
  File "C:\Users\LENOVO\Desktop\Demo\myworld\lib\site-packages\django\urls\conf.py", line 38, in include
    urlconf_module = import_module(urlconf_module)
  File "C:\Users\LENOVO\AppData\Local\Programs\Python\Python39\lib\importlib\__init__.py", line 127, in import_module
    return _bootstrap._gcd_import(name[level:], package, level)
  File "<frozen importlib._bootstrap>", line 1030, in _gcd_import
  File "<frozen importlib._bootstrap>", line 1007, in _find_and_load
  File "<frozen importlib._bootstrap>", line 986, in _find_and_load_unlocked
  File "<frozen importlib._bootstrap>", line 680, in _load_unlocked
  File "<frozen importlib._bootstrap_external>", line 850, in exec_module
  File "<frozen importlib._bootstrap>", line 228, in _call_with_frames_removed
  File "C:\Users\LENOVO\Desktop\Demo\myworld\my_tennis_club\members\urls.py", line 2, in <module>
    from . import views
  File "C:\Users\LENOVO\Desktop\Demo\myworld\my_tennis_club\members\views.py", line 3, in <module>
    from django.temaplate import loader
ModuleNotFoundError: No module named 'django.temaplate'
C:\Users\LENOVO\Desktop\Demo\myworld\my_tennis_club\my_tennis_club\settings.py changed, reloading.
Watching for file changes with StatReloader
Performing system checks...

Exception in thread django-main-thread:
Traceback (most recent call last):
  File "C:\Users\LENOVO\AppData\Local\Programs\Python\Python39\lib\threading.py", line 973, in _bootstrap_inner
    self.run()
  File "C:\Users\LENOVO\AppData\Local\Programs\Python\Python39\lib\threading.py", line 910, in run
    self._target(*self._args, **self._kwargs)
  File "C:\Users\LENOVO\Desktop\Demo\myworld\lib\site-packages\django\utils\autoreload.py", line 64, in wrapper
    fn(*args, **kwargs)
  File "C:\Users\LENOVO\Desktop\Demo\myworld\lib\site-packages\django\core\management\commands\runserver.py", line 133, in inner_run
    self.check(display_num_errors=True)
  File "C:\Users\LENOVO\Desktop\Demo\myworld\lib\site-packages\django\core\management\base.py", line 485, in check
    all_issues = checks.run_checks(
  File "C:\Users\LENOVO\Desktop\Demo\myworld\lib\site-packages\django\core\checks\registry.py", line 88, in run_checks
    new_errors = check(app_configs=app_configs, databases=databases)
  File "C:\Users\LENOVO\Desktop\Demo\myworld\lib\site-packages\django\core\checks\urls.py", line 14, in check_url_config
    return check_resolver(resolver)
  File "C:\Users\LENOVO\Desktop\Demo\myworld\lib\site-packages\django\core\checks\urls.py", line 24, in check_resolver
    return check_method()
  File "C:\Users\LENOVO\Desktop\Demo\myworld\lib\site-packages\django\urls\resolvers.py", line 494, in check
    for pattern in self.url_patterns:
  File "C:\Users\LENOVO\Desktop\Demo\myworld\lib\site-packages\django\utils\functional.py", line 57, in __get__
    res = instance.__dict__[self.name] = self.func(instance)
  File "C:\Users\LENOVO\Desktop\Demo\myworld\lib\site-packages\django\urls\resolvers.py", line 715, in url_patterns
    patterns = getattr(self.urlconf_module, "urlpatterns", self.urlconf_module)
  File "C:\Users\LENOVO\Desktop\Demo\myworld\lib\site-packages\django\utils\functional.py", line 57, in __get__
    res = instance.__dict__[self.name] = self.func(instance)
  File "C:\Users\LENOVO\Desktop\Demo\myworld\lib\site-packages\django\urls\resolvers.py", line 708, in urlconf_module
    return import_module(self.urlconf_name)
  File "C:\Users\LENOVO\AppData\Local\Programs\Python\Python39\lib\importlib\__init__.py", line 127, in import_module
    return _bootstrap._gcd_import(name[level:], package, level)
  File "<frozen importlib._bootstrap>", line 1030, in _gcd_import
  File "<frozen importlib._bootstrap>", line 1007, in _find_and_load
  File "<frozen importlib._bootstrap>", line 986, in _find_and_load_unlocked
  File "<frozen importlib._bootstrap>", line 680, in _load_unlocked
  File "<frozen importlib._bootstrap_external>", line 850, in exec_module
  File "<frozen importlib._bootstrap>", line 228, in _call_with_frames_removed
  File "C:\Users\LENOVO\Desktop\Demo\myworld\my_tennis_club\my_tennis_club\urls.py", line 21, in <module>
    path('',include('members.urls')),
  File "C:\Users\LENOVO\Desktop\Demo\myworld\lib\site-packages\django\urls\conf.py", line 38, in include
    urlconf_module = import_module(urlconf_module)
  File "C:\Users\LENOVO\AppData\Local\Programs\Python\Python39\lib\importlib\__init__.py", line 127, in import_module
    return _bootstrap._gcd_import(name[level:], package, level)
  File "<frozen importlib._bootstrap>", line 1030, in _gcd_import
  File "<frozen importlib._bootstrap>", line 1007, in _find_and_load
  File "<frozen importlib._bootstrap>", line 986, in _find_and_load_unlocked
  File "<frozen importlib._bootstrap>", line 680, in _load_unlocked
  File "<frozen importlib._bootstrap_external>", line 850, in exec_module
  File "<frozen importlib._bootstrap>", line 228, in _call_with_frames_removed
  File "C:\Users\LENOVO\Desktop\Demo\myworld\my_tennis_club\members\urls.py", line 2, in <module>
    from . import views
  File "C:\Users\LENOVO\Desktop\Demo\myworld\my_tennis_club\members\views.py", line 3, in <module>
    from django.temaplate import loader
ModuleNotFoundError: No module named 'django.temaplate'

(myworld) C:\Users\LENOVO\Desktop\Demo\myworld\my_tennis_club>py manage.py migrate
Traceback (most recent call last):
  File "C:\Users\LENOVO\Desktop\Demo\myworld\my_tennis_club\manage.py", line 22, in <module>
    main()
  File "C:\Users\LENOVO\Desktop\Demo\myworld\my_tennis_club\manage.py", line 18, in main
    execute_from_command_line(sys.argv)
  File "C:\Users\LENOVO\Desktop\Demo\myworld\lib\site-packages\django\core\management\__init__.py", line 442, in execute_from_command_line
    utility.execute()
  File "C:\Users\LENOVO\Desktop\Demo\myworld\lib\site-packages\django\core\management\__init__.py", line 436, in execute
    self.fetch_command(subcommand).run_from_argv(self.argv)
  File "C:\Users\LENOVO\Desktop\Demo\myworld\lib\site-packages\django\core\management\base.py", line 412, in run_from_argv
    self.execute(*args, **cmd_options)
  File "C:\Users\LENOVO\Desktop\Demo\myworld\lib\site-packages\django\core\management\base.py", line 458, in execute
    output = self.handle(*args, **options)
  File "C:\Users\LENOVO\Desktop\Demo\myworld\lib\site-packages\django\core\management\base.py", line 106, in wrapper
    res = handle_func(*args, **kwargs)
  File "C:\Users\LENOVO\Desktop\Demo\myworld\lib\site-packages\django\core\management\commands\migrate.py", line 100, in handle
    self.check(databases=[database])
  File "C:\Users\LENOVO\Desktop\Demo\myworld\lib\site-packages\django\core\management\base.py", line 485, in check
    all_issues = checks.run_checks(
  File "C:\Users\LENOVO\Desktop\Demo\myworld\lib\site-packages\django\core\checks\registry.py", line 88, in run_checks
    new_errors = check(app_configs=app_configs, databases=databases)
  File "C:\Users\LENOVO\Desktop\Demo\myworld\lib\site-packages\django\core\checks\urls.py", line 14, in check_url_config
    return check_resolver(resolver)
  File "C:\Users\LENOVO\Desktop\Demo\myworld\lib\site-packages\django\core\checks\urls.py", line 24, in check_resolver
    return check_method()
  File "C:\Users\LENOVO\Desktop\Demo\myworld\lib\site-packages\django\urls\resolvers.py", line 494, in check
    for pattern in self.url_patterns:
  File "C:\Users\LENOVO\Desktop\Demo\myworld\lib\site-packages\django\utils\functional.py", line 57, in __get__
    res = instance.__dict__[self.name] = self.func(instance)
  File "C:\Users\LENOVO\Desktop\Demo\myworld\lib\site-packages\django\urls\resolvers.py", line 715, in url_patterns
    patterns = getattr(self.urlconf_module, "urlpatterns", self.urlconf_module)
  File "C:\Users\LENOVO\Desktop\Demo\myworld\lib\site-packages\django\utils\functional.py", line 57, in __get__
    res = instance.__dict__[self.name] = self.func(instance)
  File "C:\Users\LENOVO\Desktop\Demo\myworld\lib\site-packages\django\urls\resolvers.py", line 708, in urlconf_module
    return import_module(self.urlconf_name)
  File "C:\Users\LENOVO\AppData\Local\Programs\Python\Python39\lib\importlib\__init__.py", line 127, in import_module
    return _bootstrap._gcd_import(name[level:], package, level)
  File "<frozen importlib._bootstrap>", line 1030, in _gcd_import
  File "<frozen importlib._bootstrap>", line 1007, in _find_and_load
  File "<frozen importlib._bootstrap>", line 986, in _find_and_load_unlocked
  File "<frozen importlib._bootstrap>", line 680, in _load_unlocked
  File "<frozen importlib._bootstrap_external>", line 850, in exec_module
  File "<frozen importlib._bootstrap>", line 228, in _call_with_frames_removed
  File "C:\Users\LENOVO\Desktop\Demo\myworld\my_tennis_club\my_tennis_club\urls.py", line 21, in <module>
    path('',include('members.urls')),
  File "C:\Users\LENOVO\Desktop\Demo\myworld\lib\site-packages\django\urls\conf.py", line 38, in include
    urlconf_module = import_module(urlconf_module)
  File "C:\Users\LENOVO\AppData\Local\Programs\Python\Python39\lib\importlib\__init__.py", line 127, in import_module
    return _bootstrap._gcd_import(name[level:], package, level)
  File "<frozen importlib._bootstrap>", line 1030, in _gcd_import
  File "<frozen importlib._bootstrap>", line 1007, in _find_and_load
  File "<frozen importlib._bootstrap>", line 986, in _find_and_load_unlocked
  File "<frozen importlib._bootstrap>", line 680, in _load_unlocked
  File "<frozen importlib._bootstrap_external>", line 850, in exec_module
  File "<frozen importlib._bootstrap>", line 228, in _call_with_frames_removed
  File "C:\Users\LENOVO\Desktop\Demo\myworld\my_tennis_club\members\urls.py", line 2, in <module>
    from . import views
  File "C:\Users\LENOVO\Desktop\Demo\myworld\my_tennis_club\members\views.py", line 3, in <module>
    from django.temaplate import loader
ModuleNotFoundError: No module named 'django.temaplate'

(myworld) C:\Users\LENOVO\Desktop\Demo\myworld\my_tennis_club>py manage.py migrate
Traceback (most recent call last):
  File "C:\Users\LENOVO\Desktop\Demo\myworld\my_tennis_club\manage.py", line 22, in <module>
    main()
  File "C:\Users\LENOVO\Desktop\Demo\myworld\my_tennis_club\manage.py", line 18, in main
    execute_from_command_line(sys.argv)
  File "C:\Users\LENOVO\Desktop\Demo\myworld\lib\site-packages\django\core\management\__init__.py", line 442, in execute_from_command_line
    utility.execute()
  File "C:\Users\LENOVO\Desktop\Demo\myworld\lib\site-packages\django\core\management\__init__.py", line 436, in execute
    self.fetch_command(subcommand).run_from_argv(self.argv)
  File "C:\Users\LENOVO\Desktop\Demo\myworld\lib\site-packages\django\core\management\base.py", line 412, in run_from_argv
    self.execute(*args, **cmd_options)
  File "C:\Users\LENOVO\Desktop\Demo\myworld\lib\site-packages\django\core\management\base.py", line 458, in execute
    output = self.handle(*args, **options)
  File "C:\Users\LENOVO\Desktop\Demo\myworld\lib\site-packages\django\core\management\base.py", line 106, in wrapper
    res = handle_func(*args, **kwargs)
  File "C:\Users\LENOVO\Desktop\Demo\myworld\lib\site-packages\django\core\management\commands\migrate.py", line 100, in handle
    self.check(databases=[database])
  File "C:\Users\LENOVO\Desktop\Demo\myworld\lib\site-packages\django\core\management\base.py", line 485, in check
    all_issues = checks.run_checks(
  File "C:\Users\LENOVO\Desktop\Demo\myworld\lib\site-packages\django\core\checks\registry.py", line 88, in run_checks
    new_errors = check(app_configs=app_configs, databases=databases)
  File "C:\Users\LENOVO\Desktop\Demo\myworld\lib\site-packages\django\core\checks\urls.py", line 14, in check_url_config
    return check_resolver(resolver)
  File "C:\Users\LENOVO\Desktop\Demo\myworld\lib\site-packages\django\core\checks\urls.py", line 24, in check_resolver
    return check_method()
  File "C:\Users\LENOVO\Desktop\Demo\myworld\lib\site-packages\django\urls\resolvers.py", line 494, in check
    for pattern in self.url_patterns:
  File "C:\Users\LENOVO\Desktop\Demo\myworld\lib\site-packages\django\utils\functional.py", line 57, in __get__
    res = instance.__dict__[self.name] = self.func(instance)
  File "C:\Users\LENOVO\Desktop\Demo\myworld\lib\site-packages\django\urls\resolvers.py", line 715, in url_patterns
    patterns = getattr(self.urlconf_module, "urlpatterns", self.urlconf_module)
  File "C:\Users\LENOVO\Desktop\Demo\myworld\lib\site-packages\django\utils\functional.py", line 57, in __get__
    res = instance.__dict__[self.name] = self.func(instance)
  File "C:\Users\LENOVO\Desktop\Demo\myworld\lib\site-packages\django\urls\resolvers.py", line 708, in urlconf_module
    return import_module(self.urlconf_name)
  File "C:\Users\LENOVO\AppData\Local\Programs\Python\Python39\lib\importlib\__init__.py", line 127, in import_module
    return _bootstrap._gcd_import(name[level:], package, level)
  File "<frozen importlib._bootstrap>", line 1030, in _gcd_import
  File "<frozen importlib._bootstrap>", line 1007, in _find_and_load
  File "<frozen importlib._bootstrap>", line 986, in _find_and_load_unlocked
  File "<frozen importlib._bootstrap>", line 680, in _load_unlocked
  File "<frozen importlib._bootstrap_external>", line 850, in exec_module
  File "<frozen importlib._bootstrap>", line 228, in _call_with_frames_removed
  File "C:\Users\LENOVO\Desktop\Demo\myworld\my_tennis_club\my_tennis_club\urls.py", line 21, in <module>
    path('',include('members.urls')),
  File "C:\Users\LENOVO\Desktop\Demo\myworld\lib\site-packages\django\urls\conf.py", line 38, in include
    urlconf_module = import_module(urlconf_module)
  File "C:\Users\LENOVO\AppData\Local\Programs\Python\Python39\lib\importlib\__init__.py", line 127, in import_module
    return _bootstrap._gcd_import(name[level:], package, level)
  File "<frozen importlib._bootstrap>", line 1030, in _gcd_import
  File "<frozen importlib._bootstrap>", line 1007, in _find_and_load
  File "<frozen importlib._bootstrap>", line 986, in _find_and_load_unlocked
  File "<frozen importlib._bootstrap>", line 680, in _load_unlocked
  File "<frozen importlib._bootstrap_external>", line 850, in exec_module
  File "<frozen importlib._bootstrap>", line 228, in _call_with_frames_removed
  File "C:\Users\LENOVO\Desktop\Demo\myworld\my_tennis_club\members\urls.py", line 2, in <module>
    from . import views
  File "C:\Users\LENOVO\Desktop\Demo\myworld\my_tennis_club\members\views.py", line 3, in <module>
    from django.temaplate import loader
ModuleNotFoundError: No module named 'django.temaplate'

(myworld) C:\Users\LENOVO\Desktop\Demo\myworld\my_tennis_club>py manage.py migrate
Operations to perform:
  Apply all migrations: admin, auth, contenttypes, sessions
Running migrations:
  Applying contenttypes.0001_initial... OK
  Applying auth.0001_initial... OK
  Applying admin.0001_initial... OK
  Applying admin.0002_logentry_remove_auto_add... OK
  Applying admin.0003_logentry_add_action_flag_choices... OK
  Applying contenttypes.0002_remove_content_type_name... OK
  Applying auth.0002_alter_permission_name_max_length... OK
  Applying auth.0003_alter_user_email_max_length... OK
  Applying auth.0004_alter_user_username_opts... OK
  Applying auth.0005_alter_user_last_login_null... OK
  Applying auth.0006_require_contenttypes_0002... OK
  Applying auth.0007_alter_validators_add_error_messages... OK
  Applying auth.0008_alter_user_username_max_length... OK
  Applying auth.0009_alter_user_last_name_max_length... OK
  Applying auth.0010_alter_group_name_max_length... OK
  Applying auth.0011_update_proxy_permissions... OK
  Applying auth.0012_alter_user_first_name_max_length... OK
  Applying sessions.0001_initial... OK

(myworld) C:\Users\LENOVO\Desktop\Demo\myworld\my_tennis_club>py manage.py runserver
Watching for file changes with StatReloader
Performing system checks...

System check identified no issues (0 silenced).
July 11, 2024 - 13:14:46
Django version 4.2.14, using settings 'my_tennis_club.settings'
Starting development server at http://127.0.0.1:8000/
Quit the server with CTRL-BREAK.

[11/Jul/2024 13:15:18] "GET /members HTTP/1.1" 301 0
[11/Jul/2024 13:15:18] "GET /members/ HTTP/1.1" 200 204
C:\Users\LENOVO\Desktop\Demo\myworld\my_tennis_club\members\models.py changed, reloading.
Watching for file changes with StatReloader
Performing system checks...

System check identified no issues (0 silenced).
July 11, 2024 - 13:19:47
Django version 4.2.14, using settings 'my_tennis_club.settings'
Starting development server at http://127.0.0.1:8000/
Quit the server with CTRL-BREAK.

C:\Users\LENOVO\Desktop\Demo\myworld\my_tennis_club\members\models.py changed, reloading.
Watching for file changes with StatReloader
Exception in thread django-main-thread:
Traceback (most recent call last):
  File "C:\Users\LENOVO\AppData\Local\Programs\Python\Python39\lib\threading.py", line 973, in _bootstrap_inner
    self.run()
  File "C:\Users\LENOVO\AppData\Local\Programs\Python\Python39\lib\threading.py", line 910, in run
    self._target(*self._args, **self._kwargs)
  File "C:\Users\LENOVO\Desktop\Demo\myworld\lib\site-packages\django\utils\autoreload.py", line 64, in wrapper
    fn(*args, **kwargs)
  File "C:\Users\LENOVO\Desktop\Demo\myworld\lib\site-packages\django\core\management\commands\runserver.py", line 125, in inner_run
    autoreload.raise_last_exception()
  File "C:\Users\LENOVO\Desktop\Demo\myworld\lib\site-packages\django\utils\autoreload.py", line 87, in raise_last_exception
    raise _exception[1]
  File "C:\Users\LENOVO\Desktop\Demo\myworld\lib\site-packages\django\core\management\__init__.py", line 394, in execute
    autoreload.check_errors(django.setup)()
  File "C:\Users\LENOVO\Desktop\Demo\myworld\lib\site-packages\django\utils\autoreload.py", line 64, in wrapper
    fn(*args, **kwargs)
  File "C:\Users\LENOVO\Desktop\Demo\myworld\lib\site-packages\django\__init__.py", line 24, in setup
    apps.populate(settings.INSTALLED_APPS)
  File "C:\Users\LENOVO\Desktop\Demo\myworld\lib\site-packages\django\apps\registry.py", line 116, in populate
    app_config.import_models()
  File "C:\Users\LENOVO\Desktop\Demo\myworld\lib\site-packages\django\apps\config.py", line 269, in import_models
    self.models_module = import_module(models_module_name)
  File "C:\Users\LENOVO\AppData\Local\Programs\Python\Python39\lib\importlib\__init__.py", line 127, in import_module
    return _bootstrap._gcd_import(name[level:], package, level)
  File "<frozen importlib._bootstrap>", line 1030, in _gcd_import
  File "<frozen importlib._bootstrap>", line 1007, in _find_and_load
  File "<frozen importlib._bootstrap>", line 986, in _find_and_load_unlocked
  File "<frozen importlib._bootstrap>", line 680, in _load_unlocked
  File "<frozen importlib._bootstrap_external>", line 846, in exec_module
  File "<frozen importlib._bootstrap_external>", line 983, in get_code
  File "<frozen importlib._bootstrap_external>", line 913, in source_to_code
  File "<frozen importlib._bootstrap>", line 228, in _call_with_frames_removed
  File "C:\Users\LENOVO\Desktop\Demo\myworld\my_tennis_club\members\models.py", line 4
    class Member(models.)
                        ^
SyntaxError: invalid syntax
C:\Users\LENOVO\Desktop\Demo\myworld\my_tennis_club\members\models.py changed, reloading.
Watching for file changes with StatReloader
Exception in thread django-main-thread:
Traceback (most recent call last):
  File "C:\Users\LENOVO\AppData\Local\Programs\Python\Python39\lib\threading.py", line 973, in _bootstrap_inner
    self.run()
  File "C:\Users\LENOVO\AppData\Local\Programs\Python\Python39\lib\threading.py", line 910, in run
    self._target(*self._args, **self._kwargs)
  File "C:\Users\LENOVO\Desktop\Demo\myworld\lib\site-packages\django\utils\autoreload.py", line 64, in wrapper
    fn(*args, **kwargs)
  File "C:\Users\LENOVO\Desktop\Demo\myworld\lib\site-packages\django\core\management\commands\runserver.py", line 125, in inner_run
    autoreload.raise_last_exception()
  File "C:\Users\LENOVO\Desktop\Demo\myworld\lib\site-packages\django\utils\autoreload.py", line 87, in raise_last_exception
    raise _exception[1]
  File "C:\Users\LENOVO\Desktop\Demo\myworld\lib\site-packages\django\core\management\__init__.py", line 394, in execute
    autoreload.check_errors(django.setup)()
  File "C:\Users\LENOVO\Desktop\Demo\myworld\lib\site-packages\django\utils\autoreload.py", line 64, in wrapper
    fn(*args, **kwargs)
  File "C:\Users\LENOVO\Desktop\Demo\myworld\lib\site-packages\django\__init__.py", line 24, in setup
    apps.populate(settings.INSTALLED_APPS)
  File "C:\Users\LENOVO\Desktop\Demo\myworld\lib\site-packages\django\apps\registry.py", line 116, in populate
    app_config.import_models()
  File "C:\Users\LENOVO\Desktop\Demo\myworld\lib\site-packages\django\apps\config.py", line 269, in import_models
    self.models_module = import_module(models_module_name)
  File "C:\Users\LENOVO\AppData\Local\Programs\Python\Python39\lib\importlib\__init__.py", line 127, in import_module
    return _bootstrap._gcd_import(name[level:], package, level)
  File "<frozen importlib._bootstrap>", line 1030, in _gcd_import
  File "<frozen importlib._bootstrap>", line 1007, in _find_and_load
  File "<frozen importlib._bootstrap>", line 986, in _find_and_load_unlocked
  File "<frozen importlib._bootstrap>", line 680, in _load_unlocked
  File "<frozen importlib._bootstrap_external>", line 846, in exec_module
  File "<frozen importlib._bootstrap_external>", line 983, in get_code
  File "<frozen importlib._bootstrap_external>", line 913, in source_to_code
  File "<frozen importlib._bootstrap>", line 228, in _call_with_frames_removed
  File "C:\Users\LENOVO\Desktop\Demo\myworld\my_tennis_club\members\models.py", line 6

    ^
IndentationError: expected an indented block
C:\Users\LENOVO\Desktop\Demo\myworld\my_tennis_club\members\models.py changed, reloading.
Watching for file changes with StatReloader
Exception in thread django-main-thread:
Traceback (most recent call last):
  File "C:\Users\LENOVO\AppData\Local\Programs\Python\Python39\lib\threading.py", line 973, in _bootstrap_inner
    self.run()
  File "C:\Users\LENOVO\AppData\Local\Programs\Python\Python39\lib\threading.py", line 910, in run
    self._target(*self._args, **self._kwargs)
  File "C:\Users\LENOVO\Desktop\Demo\myworld\lib\site-packages\django\utils\autoreload.py", line 64, in wrapper
    fn(*args, **kwargs)
  File "C:\Users\LENOVO\Desktop\Demo\myworld\lib\site-packages\django\core\management\commands\runserver.py", line 125, in inner_run
    autoreload.raise_last_exception()
  File "C:\Users\LENOVO\Desktop\Demo\myworld\lib\site-packages\django\utils\autoreload.py", line 87, in raise_last_exception
    raise _exception[1]
  File "C:\Users\LENOVO\Desktop\Demo\myworld\lib\site-packages\django\core\management\__init__.py", line 394, in execute
    autoreload.check_errors(django.setup)()
  File "C:\Users\LENOVO\Desktop\Demo\myworld\lib\site-packages\django\utils\autoreload.py", line 64, in wrapper
    fn(*args, **kwargs)
  File "C:\Users\LENOVO\Desktop\Demo\myworld\lib\site-packages\django\__init__.py", line 24, in setup
    apps.populate(settings.INSTALLED_APPS)
  File "C:\Users\LENOVO\Desktop\Demo\myworld\lib\site-packages\django\apps\registry.py", line 116, in populate
    app_config.import_models()
  File "C:\Users\LENOVO\Desktop\Demo\myworld\lib\site-packages\django\apps\config.py", line 269, in import_models
    self.models_module = import_module(models_module_name)
  File "C:\Users\LENOVO\AppData\Local\Programs\Python\Python39\lib\importlib\__init__.py", line 127, in import_module
    return _bootstrap._gcd_import(name[level:], package, level)
  File "<frozen importlib._bootstrap>", line 1030, in _gcd_import
  File "<frozen importlib._bootstrap>", line 1007, in _find_and_load
  File "<frozen importlib._bootstrap>", line 986, in _find_and_load_unlocked
  File "<frozen importlib._bootstrap>", line 680, in _load_unlocked
  File "<frozen importlib._bootstrap_external>", line 846, in exec_module
  File "<frozen importlib._bootstrap_external>", line 983, in get_code
  File "<frozen importlib._bootstrap_external>", line 913, in source_to_code
  File "<frozen importlib._bootstrap>", line 228, in _call_with_frames_removed
  File "C:\Users\LENOVO\Desktop\Demo\myworld\my_tennis_club\members\models.py", line 5
    firstname = models.
                       ^
SyntaxError: invalid syntax
C:\Users\LENOVO\Desktop\Demo\myworld\my_tennis_club\members\models.py changed, reloading.
Watching for file changes with StatReloader
Exception in thread django-main-thread:
Traceback (most recent call last):
  File "C:\Users\LENOVO\AppData\Local\Programs\Python\Python39\lib\threading.py", line 973, in _bootstrap_inner
    self.run()
  File "C:\Users\LENOVO\AppData\Local\Programs\Python\Python39\lib\threading.py", line 910, in run
    self._target(*self._args, **self._kwargs)
  File "C:\Users\LENOVO\Desktop\Demo\myworld\lib\site-packages\django\utils\autoreload.py", line 64, in wrapper
    fn(*args, **kwargs)
  File "C:\Users\LENOVO\Desktop\Demo\myworld\lib\site-packages\django\core\management\commands\runserver.py", line 125, in inner_run
    autoreload.raise_last_exception()
  File "C:\Users\LENOVO\Desktop\Demo\myworld\lib\site-packages\django\utils\autoreload.py", line 87, in raise_last_exception
    raise _exception[1]
  File "C:\Users\LENOVO\Desktop\Demo\myworld\lib\site-packages\django\core\management\__init__.py", line 394, in execute
    autoreload.check_errors(django.setup)()
  File "C:\Users\LENOVO\Desktop\Demo\myworld\lib\site-packages\django\utils\autoreload.py", line 64, in wrapper
    fn(*args, **kwargs)
  File "C:\Users\LENOVO\Desktop\Demo\myworld\lib\site-packages\django\__init__.py", line 24, in setup
    apps.populate(settings.INSTALLED_APPS)
  File "C:\Users\LENOVO\Desktop\Demo\myworld\lib\site-packages\django\apps\registry.py", line 116, in populate
    app_config.import_models()
  File "C:\Users\LENOVO\Desktop\Demo\myworld\lib\site-packages\django\apps\config.py", line 269, in import_models
    self.models_module = import_module(models_module_name)
  File "C:\Users\LENOVO\AppData\Local\Programs\Python\Python39\lib\importlib\__init__.py", line 127, in import_module
    return _bootstrap._gcd_import(name[level:], package, level)
  File "<frozen importlib._bootstrap>", line 1030, in _gcd_import
  File "<frozen importlib._bootstrap>", line 1007, in _find_and_load
  File "<frozen importlib._bootstrap>", line 986, in _find_and_load_unlocked
  File "<frozen importlib._bootstrap>", line 680, in _load_unlocked
  File "<frozen importlib._bootstrap_external>", line 850, in exec_module
  File "<frozen importlib._bootstrap>", line 228, in _call_with_frames_removed
  File "C:\Users\LENOVO\Desktop\Demo\myworld\my_tennis_club\members\models.py", line 4, in <module>
    class Member(models.Model):
  File "C:\Users\LENOVO\Desktop\Demo\myworld\my_tennis_club\members\models.py", line 5, in Member
    firstname = models.CharField(max_)
NameError: name 'max_' is not defined
C:\Users\LENOVO\Desktop\Demo\myworld\my_tennis_club\members\models.py changed, reloading.
Watching for file changes with StatReloader
Performing system checks...

System check identified no issues (0 silenced).
July 11, 2024 - 13:21:14
Django version 4.2.14, using settings 'my_tennis_club.settings'
Starting development server at http://127.0.0.1:8000/
Quit the server with CTRL-BREAK.

C:\Users\LENOVO\Desktop\Demo\myworld\my_tennis_club\members\models.py changed, reloading.
Watching for file changes with StatReloader
Performing system checks...

System check identified no issues (0 silenced).
July 11, 2024 - 13:21:41
Django version 4.2.14, using settings 'my_tennis_club.settings'
Starting development server at http://127.0.0.1:8000/
Quit the server with CTRL-BREAK.


(myworld) C:\Users\LENOVO\Desktop\Demo\myworld\my_tennis_club>py manage.py makemigrations member
No installed app with label 'member'.

(myworld) C:\Users\LENOVO\Desktop\Demo\myworld\my_tennis_club>py manage.py makemigrations member
No installed app with label 'member'.

(myworld) C:\Users\LENOVO\Desktop\Demo\myworld\my_tennis_club>py manage.py makemigrations members
Migrations for 'members':
  members\migrations\0001_initial.py
    - Create model Member

(myworld) C:\Users\LENOVO\Desktop\Demo\myworld\my_tennis_club>py manage.py migrate
Operations to perform:
  Apply all migrations: admin, auth, contenttypes, members, sessions
Running migrations:
  Applying members.0001_initial... OK

(myworld) C:\Users\LENOVO\Desktop\Demo\myworld\my_tennis_club>py manage.py sqlmigrate members 0001
BEGIN;
--
-- Create model Member
--
CREATE TABLE "members_member" ("id" integer NOT NULL PRIMARY KEY AUTOINCREMENT, "firstname" varchar(255) NOT NULL, "lastname" varchar(255) NOT NULL);
COMMIT;

(myworld) C:\Users\LENOVO\Desktop\Demo\myworld\my_tennis_club>py manage.py shell
Python 3.9.9 (tags/v3.9.9:ccb0e6a, Nov 15 2021, 18:08:50) [MSC v.1929 64 bit (AMD64)] on win32
Type "help", "copyright", "credits" or "license" for more information.
(InteractiveConsole)
>>> from member.models import Member
Traceback (most recent call last):
  File "<console>", line 1, in <module>
ModuleNotFoundError: No module named 'member'
>>> from members.models import Member
>>> Member.objects.all()
<QuerySet []>
>>> member = Member(firstname='Emil', lastname='Refness')
>>> member.save()
>>> Member.objects.all().values()
<QuerySet [{'id': 1, 'firstname': 'Emil', 'lastname': 'Refness'}]>
>>> member1 = Member(firstname='Tobias', lastname='Refness')
>>> member2 = Member(firstname='Linus', lastname='Refness')
>>> member3 = Member(firstname='Lene', lastname='Refness')
>>> member4 = Member(firstname='Stale', lastname='Refness')
>>> member5 = Member(firstname='jane', lastname='Doe')
>>> members_list = [member1,member2,member3,member4,member3]
>>> for x in members_list:
...     x.save()
...
>>> Member.objects.all().values()
<QuerySet [{'id': 1, 'firstname': 'Emil', 'lastname': 'Refness'}, {'id': 2, 'firstname': 'Tobias', 'lastname': 'Refness'}, {'id': 3, 'firstname': 'Linus', 'lastname': 'Refness'}, {'id': 4, 'firstname': 'Lene', 'lastname': 'Refness'}, {'id': 5, 'firstname': 'Stale', 'lastname': 'Refness'}]>
>>> x = Member.objects.all()[4]
>>> x.firstname
'Stale'
>>> x.firstname = stalikken
Traceback (most recent call last):
  File "<console>", line 1, in <module>
NameError: name 'stalikken' is not defined
>>> x.firstname = "stalikken"
>>> Member.objects.all().values()
<QuerySet [{'id': 1, 'firstname': 'Emil', 'lastname': 'Refness'}, {'id': 2, 'firstname': 'Tobias', 'lastname': 'Refness'}, {'id': 3, 'firstname': 'Linus', 'lastname': 'Refness'}, {'id': 4, 'firstname': 'Lene', 'lastname': 'Refness'}, {'id': 5, 'firstname': 'Stale', 'lastname': 'Refness'}]>
>>> x.save()
>>> Member.objects.all().values()
<QuerySet [{'id': 1, 'firstname': 'Emil', 'lastname': 'Refness'}, {'id': 2, 'firstname': 'Tobias', 'lastname': 'Refness'}, {'id': 3, 'firstname': 'Linus', 'lastname': 'Refness'}, {'id': 4, 'firstname': 'Lene', 'lastname': 'Refness'}, {'id': 5, 'firstname': 'stalikken', 'lastname': 'Refness'}]>
>>> x = Member.objects.all()[5]
Traceback (most recent call last):
  File "<console>", line 1, in <module>
  File "C:\Users\LENOVO\Desktop\Demo\myworld\lib\site-packages\django\db\models\query.py", line 450, in __getitem__
    return qs._result_cache[0]
IndexError: list index out of range
>>> member5 = Member(firstname='jane', lastname='Doe')
>>> member5.save()
>>> Member.objects.all().values()
<QuerySet [{'id': 1, 'firstname': 'Emil', 'lastname': 'Refness'}, {'id': 2, 'firstname': 'Tobias', 'lastname': 'Refness'}, {'id': 3, 'firstname': 'Linus', 'lastname': 'Refness'}, {'id': 4, 'firstname': 'Lene', 'lastname': 'Refness'}, {'id': 5, 'firstname': 'stalikken', 'lastname': 'Refness'}, {'id': 6, 'firstname': 'jane', 'lastname': 'Doe'}]>
>>> x = Member.objects.all()[5]
>>> x.firstname
'jane'
>>> x.delete()
(1, {'members.Member': 1})
>>> Member.objects.all().values()
<QuerySet [{'id': 1, 'firstname': 'Emil', 'lastname': 'Refness'}, {'id': 2, 'firstname': 'Tobias', 'lastname': 'Refness'}, {'id': 3, 'firstname': 'Linus', 'lastname': 'Refness'}, {'id': 4, 'firstname': 'Lene', 'lastname': 'Refness'}, {'id': 5, 'firstname': 'stalikken', 'lastname': 'Refness'}]>
>>>
KeyboardInterrupt
>>> ^Z

now exiting InteractiveConsole...

(myworld) C:\Users\LENOVO\Desktop\Demo\myworld\my_tennis_club>py manage.py makemigrations members
Traceback (most recent call last):
  File "C:\Users\LENOVO\Desktop\Demo\myworld\my_tennis_club\manage.py", line 22, in <module>
    main()
  File "C:\Users\LENOVO\Desktop\Demo\myworld\my_tennis_club\manage.py", line 18, in main
    execute_from_command_line(sys.argv)
  File "C:\Users\LENOVO\Desktop\Demo\myworld\lib\site-packages\django\core\management\__init__.py", line 442, in execute_from_command_line
    utility.execute()
  File "C:\Users\LENOVO\Desktop\Demo\myworld\lib\site-packages\django\core\management\__init__.py", line 416, in execute
    django.setup()
  File "C:\Users\LENOVO\Desktop\Demo\myworld\lib\site-packages\django\__init__.py", line 24, in setup
    apps.populate(settings.INSTALLED_APPS)
  File "C:\Users\LENOVO\Desktop\Demo\myworld\lib\site-packages\django\apps\registry.py", line 116, in populate
    app_config.import_models()
  File "C:\Users\LENOVO\Desktop\Demo\myworld\lib\site-packages\django\apps\config.py", line 269, in import_models
    self.models_module = import_module(models_module_name)
  File "C:\Users\LENOVO\AppData\Local\Programs\Python\Python39\lib\importlib\__init__.py", line 127, in import_module
    return _bootstrap._gcd_import(name[level:], package, level)
  File "<frozen importlib._bootstrap>", line 1030, in _gcd_import
  File "<frozen importlib._bootstrap>", line 1007, in _find_and_load
  File "<frozen importlib._bootstrap>", line 986, in _find_and_load_unlocked
  File "<frozen importlib._bootstrap>", line 680, in _load_unlocked
  File "<frozen importlib._bootstrap_external>", line 850, in exec_module
  File "<frozen importlib._bootstrap>", line 228, in _call_with_frames_removed
  File "C:\Users\LENOVO\Desktop\Demo\myworld\my_tennis_club\members\models.py", line 4, in <module>
    class Member(models.Model):
  File "C:\Users\LENOVO\Desktop\Demo\myworld\my_tennis_club\members\models.py", line 7, in Member
    phone = models.IntergerField()
AttributeError: module 'django.db.models' has no attribute 'IntergerField'

(myworld) C:\Users\LENOVO\Desktop\Demo\myworld\my_tennis_club>py manage.py makemigrations members
It is impossible to add a non-nullable field 'joined_date' to member without specifying a default. This is because the database needs something to populate existing rows.
Please select a fix:
 1) Provide a one-off default now (will be set on all existing rows with a null value for this column)
 2) Quit and manually define a default value in models.py.
Select an option: 2

(myworld) C:\Users\LENOVO\Desktop\Demo\myworld\my_tennis_club>py manage.py makemigrations members
Migrations for 'members':
  members\migrations\0002_member_joined_date_member_phone.py
    - Add field joined_date to member
    - Add field phone to member

(myworld) C:\Users\LENOVO\Desktop\Demo\myworld\my_tennis_club>py manage.py migrate
Operations to perform:
  Apply all migrations: admin, auth, contenttypes, members, sessions
Running migrations:
  Applying members.0002_member_joined_date_member_phone... OK

(myworld) C:\Users\LENOVO\Desktop\Demo\myworld\my_tennis_club>py manage.py shell
Python 3.9.9 (tags/v3.9.9:ccb0e6a, Nov 15 2021, 18:08:50) [MSC v.1929 64 bit (AMD64)] on win32
Type "help", "copyright", "credits" or "license" for more information.
(InteractiveConsole)
>>> from models.members import Member
Traceback (most recent call last):
  File "<console>", line 1, in <module>
ModuleNotFoundError: No module named 'models'
>>> from members.models import Member
>>> x = Member.objects.all()[0]
>>> x.phone = 55687420
>>> x.joined_date = '2010-01-05'
>>> x.save()
>>> Member.objects.all().values()
<QuerySet [{'id': 1, 'firstname': 'Emil', 'lastname': 'Refness', 'phone': 55687420, 'joined_date': datetime.date(2010, 1, 5)}, {'id': 2, 'firstname': 'Tobias', 'lastname': 'Refness', 'phone': None, 'joined_date': None}, {'id': 3, 'firstname': 'Linus', 'lastname': 'Refness', 'phone': None, 'joined_date': None}, {'id': 4, 'firstname': 'Lene', 'lastname': 'Refness', 'phone': None, 'joined_date': None}, {'id': 5, 'firstname': 'stalikken', 'lastname': 'Refness', 'phone': None, 'joined_date': None}]>
>>>